<?xml version="1.0" encoding="utf-8"?>
<!-- This URDF is a modified version of https://git.barrett.com/software/barrett-ros2-pkg/-/blob/devel/wam_sim/launch/wam4dof/wam4dof.urdf -->

<robot name="wam4dof">


  <link name="world"/>


  <link name="base_link">
    <inertial>
      <origin
        xyz="3.40104668810698E-05 0.0736066059361039 -0.0587577266799806"
        rpy="0 0 0" />
      <mass
        value="13.5476126893973" />
      <inertia
        ixx="0.156470957074821"
        ixy="-4.03291630164834E-05"
        ixz="4.63998145785351E-05"
        iyy="0.214731752462203"
        iyz="0.00513845865911243"
        izz="0.108286175637366" />
    </inertial>
    <!--<visual>-->
      <!--<origin xyz="0 0 0" rpy="0 0 0" />-->
      <!--<geometry>-->
        <!--<mesh filename="meshes/base_link.STL" />-->
      <!--</geometry>-->
      <!--<material name="">-->
        <!--<color rgba="0.792156862745098 0.819607843137255 0.933333333333333 1" />-->
      <!--</material>-->
    <!--</visual>-->
    <!--<collision>-->
      <!--<origin xyz="0 0 0" rpy="0 0 0" />-->
      <!--<geometry>-->
        <!--<mesh filename="meshes/base_link.STL" />-->
      <!--</geometry>-->
    <!--</collision>-->
  </link>


  <link name="first_link">
    <inertial>
      <origin
        xyz="2.53990162847128E-08 0.104881717494166 3.04922796016718E-09"
        rpy="0 0 0" />
      <mass
        value="17.3731551398704" />
      <inertia
        ixx="0.276162321852689"
        ixy="5.20061008372045E-08"
        ixz="7.60373821026883E-08"
        iyy="0.237968754825239"
        iyz="3.79403873882493E-09"
        izz="0.145688610159368" />
    </inertial>
    <!--<visual>-->
      <!--<origin xyz="0 0 0" rpy="0 0 0" />-->
      <!--<geometry>-->
        <!--<mesh filename="meshes/FirstLink.STL" />-->
      <!--</geometry>-->
      <!--<material name="">-->
        <!--<color rgba="0.796078431372549 0.796078431372549 0.752941176470588 1" />-->
      <!--</material>-->
    <!--</visual>-->
    <!--<collision>-->
      <!--<origin xyz="0 0 0" rpy="0 0 0" />-->
      <!--<geometry>-->
        <!--<mesh filename="meshes/FirstLink.STL" />-->
      <!--</geometry>-->
    <!--</collision>-->
  </link>


  <link name="second_link">
    <inertial>
      <origin
        xyz="-3.3073356588952E-06 0.0504592578779876 -1.9386722993241E-05"
        rpy="0 0 0" />
      <mass
        value="0.617554855470771" />
      <inertia
        ixx="0.00258552588913393"
        ixy="-1.52178232455456E-08"
        ixz="-4.72455503359287E-08"
        iyy="0.00186310872414462"
        iyz="3.58033312144958E-08"
        izz="0.00227630686304741" />
    </inertial>
    <!--<visual>-->
      <!--<origin xyz="0 0 0" rpy="0 0 0" />-->
      <!--<geometry>-->
        <!--<mesh filename="meshes/SecondLink.STL" />-->
      <!--</geometry>-->
      <!--<material name="">-->
        <!--<color rgba="0.796078431372549 0.796078431372549 0.752941176470588 1" />-->
      <!--</material>-->
    <!--</visual>-->
    <!--<collision>-->
      <!--<origin xyz="0 0 0" rpy="0 0 0" />-->
      <!--<geometry>-->
        <!--<mesh filename="meshes/SecondLink.STL" />-->
      <!--</geometry>-->
    <!--</collision>-->
  </link>


  <link name="third_link">
    <inertial>
      <origin
        xyz="9.06095709371319E-06 0.79471468339664 -0.0130869016439969"
        rpy="0 0 0" />
      <mass
        value="1.38872635233445" />
      <inertia
        ixx="0.0300789785129619"
        ixy="-1.13635275781099E-06"
        ixz="2.68391703177075E-07"
        iyy="0.00292729996562077"
        iyz="0.00176956641651549"
        izz="0.0304265850675373" />
    </inertial>
    <!--<visual>-->
      <!--<origin xyz="0 0 0" rpy="0 0 0" />-->
      <!--<geometry>-->
        <!--<mesh filename="meshes/ThirdLink.STL" />-->
      <!--</geometry>-->
      <!--<material name="">-->
        <!--<color rgba="0.898039215686275 0.917647058823529 0.929411764705882 1" />-->
      <!--</material>-->
    <!--</visual>-->
    <!--<collision>-->
      <!--<origin xyz="0 0 0" rpy="0 0 0" />-->
      <!--<geometry>-->
        <!--<mesh filename="meshes/ThirdLink.STL" />-->
      <!--</geometry>-->
    <!--</collision>-->
  </link>


  <link name="fourth_link">
    <inertial>
      <origin
        xyz="4.97245046301318E-07 0.0449944772820914 0.235880484538515"
        rpy="0 0 0" />
      <mass
        value="176061.840482555" />
      <inertia
        ixx="702.26848763124"
        ixy="-0.0381965038623444"
        ixz="-0.0039041419617575"
        iyy="702.827652770772"
        iyz="-0.0153100690126369"
        izz="299.798441788385" />
    </inertial>
    <!--<visual>-->
      <!--<origin xyz="0 0 0" rpy="0 0 0" />-->
      <!--<geometry>-->
        <!--<mesh filename="meshes/FourthLink.STL" />-->
      <!--</geometry>-->
      <!--<material name="">-->
        <!--<color rgba="0.666666666666667 0.63921568627451 0.556862745098039 1" />-->
      <!--</material>-->
    <!--</visual>-->
    <!--<collision>-->
      <!--<origin xyz="0 0 0" rpy="0 0 0" />-->
      <!--<geometry>-->
        <!--<mesh filename="meshes/FourthLink.STL" />-->
      <!--</geometry>-->
    <!--</collision>-->
  </link>


  <link name="tool_plate" />


  <joint name="wam_basejoint" type="fixed">
    <parent link="world"/>
    <child link="base_link"/>
    <origin rpy="0 0 1.5707963267948966" xyz="0 0 0.84"/>
  </joint>


  <joint name="q1" type="revolute">
    <origin xyz="0 0 0.16" rpy="1.570796327948966 0 1.570796327948966" />
    <parent link="base_link" />
    <child link="first_link" />
    <axis xyz="0 1 0" />
    <limit lower="-2.6" upper="2.6" effort="0" velocity="0" />
  </joint>


  <joint name="q2" type="revolute">
    <origin xyz="0 0.186 0" rpy="3.141592653589793 -1.570796327948966 3.141592653589793" />
    <parent link="first_link" />
    <child link="second_link" />
    <axis xyz="1 0 0" />
    <limit lower="-2" upper="2" effort="0" velocity="0" />
  </joint>


  <joint name="q3" type="revolute">
    <origin xyz="0 -0.346 0" rpy="3.141592653589793 0 -3.141592653589793" />
    <parent link="second_link" />
    <child link="third_link" />
    <axis xyz="0 1 0" />
    <limit lower="-2.8" upper="2.8" effort="0" velocity="0" />
  </joint>


  <joint name="q4" type="revolute">
    <origin xyz="0 0.896 -0.045" rpy="1.570796327948966 0 3.141592653589793" />
    <parent link="third_link" />
    <child link="fourth_link" />
    <axis xyz="1 0 0" />
    <limit lower="-0.9" upper="3.1" effort="0" velocity="0" />
  </joint>


  <joint name="tool_plate_fixed" type="fixed">
    <parent link="fourth_link"/>
    <child link="tool_plate" />
    <origin xyz="0 0.045 0.358" rpy="1.570796327948966 0 0" />
  </joint>

</robot>
